/usr/local/lib/python3.12/site-packages/coffea/nanoevents/schemas/fcc.py:5: FutureWarning: In version 2025.1.0 (target date: 2024-12-31 11:59:59-06:00), this will be an error.
To raise these warnings as errors (and get stack traces to find out where they're called), run
    import warnings
    warnings.filterwarnings("error", module="coffea.*")
after the first `import coffea` or use `@pytest.mark.filterwarnings("error:::coffea.*")` in pytest.
Issue: coffea.nanoevents.methods.vector will be removed and replaced with scikit-hep vector. Nanoevents schemas internal to coffea will be migrated. Otherwise please consider using that package!.
  from coffea.nanoevents.methods import vector
/usr/local/lib/python3.12/site-packages/coffea/util.py:226: UserWarning: Skipping _intMap as it is not interpretable by Uproot
  warnings.warn(
/usr/local/lib/python3.12/site-packages/coffea/util.py:234: UserWarning: Skipping _intMap.first as it is not interpretable by Uproot
  warnings.warn(
/usr/local/lib/python3.12/site-packages/coffea/util.py:234: UserWarning: Skipping _intMap.second as it is not interpretable by Uproot
  warnings.warn(
/usr/local/lib/python3.12/site-packages/coffea/util.py:226: UserWarning: Skipping _floatMap as it is not interpretable by Uproot
  warnings.warn(
/usr/local/lib/python3.12/site-packages/coffea/util.py:234: UserWarning: Skipping _floatMap.first as it is not interpretable by Uproot
  warnings.warn(
/usr/local/lib/python3.12/site-packages/coffea/util.py:234: UserWarning: Skipping _floatMap.second as it is not interpretable by Uproot
  warnings.warn(
/usr/local/lib/python3.12/site-packages/coffea/util.py:226: UserWarning: Skipping _stringMap as it is not interpretable by Uproot
  warnings.warn(
/usr/local/lib/python3.12/site-packages/coffea/util.py:234: UserWarning: Skipping _stringMap.first as it is not interpretable by Uproot
  warnings.warn(
/usr/local/lib/python3.12/site-packages/coffea/util.py:234: UserWarning: Skipping _stringMap.second as it is not interpretable by Uproot
  warnings.warn(
Traceback (most recent call last):
  File "/pool/condor/dir_860578/job_472.py", line 18, in <module>
    computed = dask.compute(to_compute)
               ^^^^^^^^^^^^^^^^^^^^^^^^
  File "/usr/local/lib/python3.12/site-packages/dask/base.py", line 660, in compute
    results = schedule(dsk, keys, **kwargs)
              ^^^^^^^^^^^^^^^^^^^^^^^^^^^^^
  File "/usr/local/lib/python3.12/site-packages/uproot/_dask.py", line 1345, in __call__
    result, _ = self._call_impl(
                ^^^^^^^^^^^^^^^^
  File "/usr/local/lib/python3.12/site-packages/uproot/_dask.py", line 1298, in _call_impl
    return self.read_tree(
           ^^^^^^^^^^^^^^^
  File "/usr/local/lib/python3.12/site-packages/uproot/_dask.py", line 985, in read_tree
    mapping = self.form_mapping_info.load_buffers(
              ^^^^^^^^^^^^^^^^^^^^^^^^^^^^^^^^^^^^
  File "/usr/local/lib/python3.12/site-packages/coffea/nanoevents/factory.py", line 157, in load_buffers
    arrays = tree.arrays(
             ^^^^^^^^^^^^
  File "/usr/local/lib/python3.12/site-packages/uproot/behaviors/TBranch.py", line 832, in arrays
    _ranges_or_baskets_to_arrays(
  File "/usr/local/lib/python3.12/site-packages/uproot/behaviors/TBranch.py", line 3133, in _ranges_or_baskets_to_arrays
    uproot.source.futures.delayed_raise(*obj)
  File "/usr/local/lib/python3.12/site-packages/uproot/source/futures.py", line 38, in delayed_raise
    raise exception_value.with_traceback(traceback)
  File "/usr/local/lib/python3.12/site-packages/uproot/behaviors/TBranch.py", line 3048, in chunk_to_basket
    basket = uproot.models.TBasket.Model_TBasket.read(
             ^^^^^^^^^^^^^^^^^^^^^^^^^^^^^^^^^^^^^^^^^
  File "/usr/local/lib/python3.12/site-packages/uproot/model.py", line 854, in read
    self.read_members(chunk, cursor, context, file)
  File "/usr/local/lib/python3.12/site-packages/uproot/models/TBasket.py", line 227, in read_members
    ) = cursor.fields(chunk, _tbasket_format1, context)
        ^^^^^^^^^^^^^^^^^^^^^^^^^^^^^^^^^^^^^^^^^^^^^^^
  File "/usr/local/lib/python3.12/site-packages/uproot/source/cursor.py", line 201, in fields
    return format.unpack(chunk.get(start, stop, self, context))
                         ^^^^^^^^^^^^^^^^^^^^^^^^^^^^^^^^^^^^^
  File "/usr/local/lib/python3.12/site-packages/uproot/source/chunk.py", line 446, in get
    self.wait(insist=stop)
  File "/usr/local/lib/python3.12/site-packages/uproot/source/chunk.py", line 388, in wait
    self._raw_data = numpy.frombuffer(self._future.result(), dtype=self._dtype)
                                      ^^^^^^^^^^^^^^^^^^^^^
  File "/usr/local/lib/python3.12/site-packages/uproot/source/coalesce.py", line 39, in result
    return self._parent.result(timeout=timeout)[self._s]
           ^^^^^^^^^^^^^^^^^^^^^^^^^^^^^^^^^^^^
  File "/usr/local/lib/python3.12/site-packages/uproot/source/coalesce.py", line 39, in result
    return self._parent.result(timeout=timeout)[self._s]
           ^^^^^^^^^^^^^^^^^^^^^^^^^^^^^^^^^^^^
  File "/usr/local/lib/python3.12/site-packages/fsspec_xrootd/xrootd.py", line 657, in _cat_ranges
    results = await _run_coros_in_chunks(coros, batch_size=batch_size, nofiles=True)
              ^^^^^^^^^^^^^^^^^^^^^^^^^^^^^^^^^^^^^^^^^^^^^^^^^^^^^^^^^^^^^^^^^^^^^^
  File "/usr/local/lib/python3.12/site-packages/fsspec/asyn.py", line 268, in _run_coros_in_chunks
    result, k = await done.pop()
                ^^^^^^^^^^^^^^^^
  File "/usr/local/lib/python3.12/site-packages/fsspec/asyn.py", line 245, in _run_coro
    return await asyncio.wait_for(coro, timeout=timeout), i
           ^^^^^^^^^^^^^^^^^^^^^^^^^^^^^^^^^^^^^^^^^^^^^
  File "/usr/local/lib/python3.12/asyncio/tasks.py", line 520, in wait_for
    return await fut
           ^^^^^^^^^
  File "/usr/local/lib/python3.12/site-packages/fsspec_xrootd/xrootd.py", line 617, in _cat_vector_read
    raise OSError(f"File did not vector_read properly: {status.message}")
OSError: File did not vector_read properly: [ERROR] Operation expired
